

~~~~~~~~~~~~~~~~~~~~~~~~~~~~~~~~~~~~~~~~~~~~~~~~~~~
Title:  .
-----------------------2016-01-18[Jan-Mon]18-49PM

virtual host redirect subdomain to port

http://stackoverflow.com/questions/12715195/how-to-forward-a-subdomain-to-a-new-port-on-the-same-ip-address

http://stackoverflow.com/questions/17570845/forwarding-from-subdomain-to-port-not-working?rq=1


<VirtualHost *:80>
    ServerName dj162.v206b1.local
    redirect / v206b1.local:8988
</VirtualHost>



[Mon Jan 18 22:09:17.581501 2016] [:error] [pid 1391] [remote 192.168.88.94:3645] mod_wsgi (pid=1391): Target WSGI script '/var/www/html/django/apache/dj162.wsgi' cannot be loaded as Python module.
[Mon Jan 18 22:09:17.581523 2016] [:error] [pid 1391] [remote 192.168.88.94:3645] mod_wsgi (pid=1391): Exception occurred processing WSGI script '/var/www/html/django/apache/dj162.wsgi'.
[Mon Jan 18 22:09:17.581536 2016] [:error] [pid 1391] [remote 192.168.88.94:3645] Traceback (most recent call last):
[Mon Jan 18 22:09:17.581555 2016] [:error] [pid 1391] [remote 192.168.88.94:3645]   File "/var/www/html/django/apache/dj162.wsgi", line 23, in <module>
[Mon Jan 18 22:09:17.581574 2016] [:error] [pid 1391] [remote 192.168.88.94:3645]     application = get_wsgi_application()
[Mon Jan 18 22:09:17.581580 2016] [:error] [pid 1391] [remote 192.168.88.94:3645]   File "/usr/local/lib/python2.7/dist-packages/django/core/wsgi.py", line 14, in get_wsgi_application
[Mon Jan 18 22:09:17.581590 2016] [:error] [pid 1391] [remote 192.168.88.94:3645]     django.setup()
[Mon Jan 18 22:09:17.581594 2016] [:error] [pid 1391] [remote 192.168.88.94:3645]   File "/usr/local/lib/python2.7/dist-packages/django/__init__.py", line 18, in setup
[Mon Jan 18 22:09:17.581601 2016] [:error] [pid 1391] [remote 192.168.88.94:3645]     apps.populate(settings.INSTALLED_APPS)
[Mon Jan 18 22:09:17.581605 2016] [:error] [pid 1391] [remote 192.168.88.94:3645]   File "/usr/local/lib/python2.7/dist-packages/django/apps/registry.py", line 78, in populate
[Mon Jan 18 22:09:17.581612 2016] [:error] [pid 1391] [remote 192.168.88.94:3645]     raise RuntimeError("populate() isn't reentrant")
[Mon Jan 18 22:09:17.581621 2016] [:error] [pid 1391] [remote 192.168.88.94:3645] RuntimeError: populate() isn't reentrant


<VirtualHost *:80>
    ServerName fsqla.v206b1.local
    redirect / v206b1.local:918
</VirtualHost>


try:
<VirtualHost *:80>
    ServerName strap.v206b1.local
    redirect / v206b1.local/test2/strap179
</VirtualHost>


~~~~~~~~~~~~~~~~~~~~~~~~~~~~~~~~~~~~~~~~~~~~~~~~~~~

_____________

